Workbook

Sheet Sheet1
A1: IBM & OLYMPIC GAMES 2026 Guessing Game | J1: Game Date | K1: 46064 | P1: 46065 | Y1: 46066 | AH1: 46067 | AQ1: 46068 | AZ1: 46070 | BI1: 46071 | BR1: 46073 | BW1: 46074 | BZ1: 46074
J2: Time: GMT +1 | K2: 0.69444444 | M2: 0.88194444 | P2: 0.50694444 | R2: 0.69444444 | T2: 0.88194444 | Y2: 0.50694444 | AC2: 0.69444444 | AE2: 0.88194444 | AH2: 0.50694444 | AL2: 0.69444444 | AN2: 0.88194444 | AQ2: 0.50694444 | AS2: 0.69444444 | AU2: 0.79861111 | AW2: 0.88194444 | AZ2: 0.50694444 | BD2: 0.69444444 | BF2: 0.88194444 | BI2: 0.50694444 | BK2: 0.69444444 | BM2: 0.75694444 | BO2: 0.88194444 | BR2: 0.69444444 | BT2: 0.88194444
A3: Rules: Guess just final score, so no draws can happen!!!. If you guess exact score of match: 4pts, if you guess the winner of match and number of goals scored by home or away team: 2pts, if you guess just the winner: 1pts. In PLAY OFF you receive +1 point for each mentioned scenario | J3: Matches | K3: SVK | L3: Points | M3: SWE | N3: Points | P3: SUI | Q3: Points | R3: CZE | S3: Points | T3: LAT | U3: Points | V3: GER | W3: Points | Y3: FIN | Z3: Points | AA3: ITA | AB3: Points | AC3: FRA | AD3: Points | AE3: CAN | AF3: Points | AH3: SWE | AI3: Points | AJ3: GER | AK3: Points | AL3: FIN | AM3: Points | AN3: USA | AO3: Points | AQ3: SUI | AR3: Points | AS3: CAN | AT3: Points | AU3: DEN | AV3: Points | AW3: USA | AX3: Points | AZ3: TBD | BA3: Points | BB3: TBD | BC3: Points | BD3: TBD | BE3: Points | BF3: TBD | BG3: Points | BI3: TBD | BJ3: Points | BK3: TBD | BL3: Points | BM3: TBD | BN3: Points | BO3: TBD | BP3: Points | BR3: TBD | BS3: Points | BT3: TBD | BU3: Points | BW3: TBD | BX3: Points | BZ3: TBD | CA3: Points
K4: vs | M4: vs | P4: vs | R4: vs | T4: vs | V4: vs | Y4: vs | AA4: vs | AC4: vs | AE4: vs | AH4: vs | AJ4: vs | AL4: vs | AN4: vs | AQ4: vs | AS4: vs | AU4: vs | AW4: vs | AZ4: vs | BB4: vs | BD4: vs | BF4: vs | BI4: vs | BK4: vs | BM4: vs | BO4: vs | BR4: vs | BT4: vs | BW4: vs | BZ4: vs
K5: FIN | M5: ITA | P5: FRA | R5: CAN | T5: USA | V5: DEN | Y5: SWE | AA5: SVK | AC5: CZE | AE5: SUI | AH5: SVK | AJ5: LAT | AL5: ITA | AN5: DEN | AQ5: CZE | AS5: FRA | AU5: LAT | AW5: GER | AZ5: TBD | BB5: TBD | BD5: TBD | BF5: TBD | BI5: TBD | BK5: TBD | BM5: TBD | BO5: TBD | BR5: TBD | BT5: TBD | BW5: TBD | BZ5: TBD
A6: ID | B6: Name | C6: Mail | D6: Country | E6: Filled matches | F6: Accurate guesses | G6: Group-stage Points | H6: Play-off Points | I6: Total Points | J6: Results:
A7: 1 | B7: Peter Niroda | C7: peter.niroda@sk.ibm.cm | D7: Slovakia | E7: =IF(K7<>"",1,0)+IF(M7<>"",1,0)+IF(P7<>"",1,0)+IF(R7<>"",1,0)+IF(T7<>"",1,0)+IF(V7<>"",1,0)+IF(Y7<>"",1,0)+IF(AA7<>"",1,0)+IF(AC7<>"",1,0)+IF(AE7<>"",1,0)+IF(AH7<>"",1,0)+IF(AJ7<>"",1,0)+IF(AL7<>"",1,0)+IF(AN7<>"",1,0)+IF(AQ7<>"",1,0)+IF(AS7<>"",1,0)+IF(AU7<>"",1,0)+IF(AW7<>"",1,0)+IF(AZ7<>"",1,0)+IF(BB7<>"",1,0)+IF(BD7<>"",1,0)+IF(BF7<>"",1,0)+IF(BI7<>"",1,0)+IF(BK7<>"",1,0)+IF(BM7<>"",1,0)+IF(BO7<>"",1,0) +IF(BR7<>"",1,0) +IF(BT7<>"",1,0) +IF(BW7<>"",1,0) +IF(BZ7<>"",1,0) -> 18 | F7: =IF(L7=4,1,0)+IF(N7=4,1,0)+IF(Q7=4,1,0)+IF(S7=4,1,0)+IF(U7=4,1,0)+IF(W7=4,1,0)+IF(Z7=4,1,0)+IF(AB7=4,1,0)+IF(AD7=4,1,0)+IF(AF7=4,1,0)+IF(AI7=4,1,0)+IF(AK7=4,1,0)+IF(AM7=4,1,0)+IF(AO7=4,1,0)+IF(AR7=4,1,0)+IF(AT7=4,1,0)+IF(AV7=4,1,0)+IF(AX7=4,1,0)+IF(BA7=5,1,0)+IF(BC7=5,1,0)+IF(BE7=5,1,0)+IF(BG7=5,1,0)+IF(BJ7=5,1,0)+IF(BL7=5,1,0)+IF(BN7=5,1,0)+IF(BP7=5,1,0) +IF(BS7=5,1,0) +IF(BU7=5,1,0) +IF(BX7=5,1,0) +IF(CA7=5,1,0) -> 0 | G7: =L7+N7+Q7+S7+U7+W7+Z7+AB7+AD7+AF7+AI7+AK7+AM7+AO7+AR7+AT7+AV7+AX7 -> 0 | H7: =BA7+BC7+BE7+BG7+BJ7+BL7+BN7+BP7 +BS7 +BU7 +BX7 +CA7 -> 0 | I7: =G7+H7 -> 0 | K7: 0:4 | L7: =_xlfn.LET( _xlpm.FinalScore, TRIM(SUBSTITUTE($K$6," ","")), _xlpm.UserGuess, TRIM(SUBSTITUTE(K7," ","")), _xlpm.FinalHome, VALUE(LEFT(_xlpm.FinalScore, FIND(":", _xlpm.FinalScore)-1)), _xlpm.FinalAway, VALUE(MID(_xlpm.FinalScore, FIND(":", _xlpm.FinalScore)+1, LEN(_xlpm.FinalScore))), _xlpm.GuessHome, VALUE(LEFT(_xlpm.UserGuess, FIND(":", _xlpm.UserGuess)-1)), _xlpm.GuessAway, VALUE(MID(_xlpm.UserGuess, FIND(":", _xlpm.UserGuess)+1, LEN(_xlpm.UserGuess))), _xlpm.FinalDiff, _xlpm.FinalHome - _xlpm.FinalAway, _xlpm.GuessDiff, _xlpm.GuessHome - _xlpm.GuessAway, IF( OR($K$6="", K7=""), 0 +N("If final or guess is missing, 0 points"), IF( AND(_xlpm.FinalHome=_xlpm.GuessHome, _xlpm.FinalAway=_xlpm.GuessAway), 4 +N("Exact score guessed, 4 points"), IF( AND( SIGN(_xlpm.FinalDiff) = SIGN(_xlpm.GuessDiff), OR(_xlpm.FinalHome=_xlpm.GuessHome, _xlpm.FinalAway=_xlpm.GuessAway) ), 2 +N("Winner and one side score guessed, 2 points"), IF( SIGN(_xlpm.FinalDiff) = SIGN(_xlpm.GuessDiff), 1 +N("Only winner guessed, 1 point"), 0 +N("Wrong guess, 0 points") ) ) ) ) ) -> 0 | M7: 6:0 | N7: =_xlfn.LET( _xlpm.FinalScore, TRIM(SUBSTITUTE($M$6," ","")), _xlpm.UserGuess, TRIM(SUBSTITUTE(M7," ","")), _xlpm.FinalHome, VALUE(LEFT(_xlpm.FinalScore, FIND(":", _xlpm.FinalScore)-1)), _xlpm.FinalAway, VALUE(MID(_xlpm.FinalScore, FIND(":", _xlpm.FinalScore)+1, LEN(_xlpm.FinalScore))), _xlpm.GuessHome, VALUE(LEFT(_xlpm.UserGuess, FIND(":", _xlpm.UserGuess)-1)), _xlpm.GuessAway, VALUE(MID(_xlpm.UserGuess, FIND(":", _xlpm.UserGuess)+1, LEN(_xlpm.UserGuess))), _xlpm.FinalDiff, _xlpm.FinalHome - _xlpm.FinalAway, _xlpm.GuessDiff, _xlpm.GuessHome - _xlpm.GuessAway, IF( OR($M$6="", M7=""), 0 +N("If final or guess is missing, 0 points"), IF( AND(_xlpm.FinalHome=_xlpm.GuessHome, _xlpm.FinalAway=_xlpm.GuessAway), 4 +N("Exact score guessed, 4 points"), IF( AND( SIGN(_xlpm.FinalDiff) = SIGN(_xlpm.GuessDiff), OR(_xlpm.FinalHome=_xlpm.GuessHome, _xlpm.FinalAway=_xlpm.GuessAway) ), 2 +N("Winner and one side score guessed, 2 points"), IF( SIGN(_xlpm.FinalDiff) = SIGN(_xlpm.GuessDiff), 1 +N("Only winner guessed, 1 point"), 0 +N("Wrong guess, 0 points") ) ) ) ) ) -> 0 | P7: 5:1 | Q7: =_xlfn.LET( _xlpm.FinalScore, TRIM(SUBSTITUTE($P$6," ","")), _xlpm.UserGuess, TRIM(SUBSTITUTE(P7," ","")), _xlpm.FinalHome, VALUE(LEFT(_xlpm.FinalScore, FIND(":", _xlpm.FinalScore)-1)), _xlpm.FinalAway, VALUE(MID(_xlpm.FinalScore, FIND(":", _xlpm.FinalScore)+1, LEN(_xlpm.FinalScore))), _xlpm.GuessHome, VALUE(LEFT(_xlpm.UserGuess, FIND(":", _xlpm.UserGuess)-1)), _xlpm.GuessAway, VALUE(MID(_xlpm.UserGuess, FIND(":", _xlpm.UserGuess)+1, LEN(_xlpm.UserGuess))), _xlpm.FinalDiff, _xlpm.FinalHome - _xlpm.FinalAway, _xlpm.GuessDiff, _xlpm.GuessHome - _xlpm.GuessAway, IF( OR($P$6="", P7=""), 0 +N("If final or guess is missing, 0 points"), IF( AND(_xlpm.FinalHome=_xlpm.GuessHome, _xlpm.FinalAway=_xlpm.GuessAway), 4 +N("Exact score guessed, 4 points"), IF( AND( SIGN(_xlpm.FinalDiff) = SIGN(_xlpm.GuessDiff), OR(_xlpm.FinalHome=_xlpm.GuessHome, _xlpm.FinalAway=_xlpm.GuessAway) ), 2 +N("Winner and one side score guessed, 2 points"), IF( SIGN(_xlpm.FinalDiff) = SIGN(_xlpm.GuessDiff), 1 +N("Only winner guessed, 1 point"), 0 +N("Wrong guess, 0 points") ) ) ) ) ) -> 0 | R7: 1:4 | S7: =_xlfn.LET( _xlpm.FinalScore, TRIM(SUBSTITUTE($R$6," ","")), _xlpm.UserGuess, TRIM(SUBSTITUTE(R7," ","")), _xlpm.FinalHome, VALUE(LEFT(_xlpm.FinalScore, FIND(":", _xlpm.FinalScore)-1)), _xlpm.FinalAway, VALUE(MID(_xlpm.FinalScore, FIND(":", _xlpm.FinalScore)+1, LEN(_xlpm.FinalScore))), _xlpm.GuessHome, VALUE(LEFT(_xlpm.UserGuess, FIND(":", _xlpm.UserGuess)-1)), _xlpm.GuessAway, VALUE(MID(_xlpm.UserGuess, FIND(":", _xlpm.UserGuess)+1, LEN(_xlpm.UserGuess))), _xlpm.FinalDiff, _xlpm.FinalHome - _xlpm.FinalAway, _xlpm.GuessDiff, _xlpm.GuessHome - _xlpm.GuessAway, IF( OR($R$6="", R7=""), 0 +N("If final or guess is missing, 0 points"), IF( AND(_xlpm.FinalHome=_xlpm.GuessHome, _xlpm.FinalAway=_xlpm.GuessAway), 4 +N("Exact score guessed, 4 points"), IF( AND( SIGN(_xlpm.FinalDiff) = SIGN(_xlpm.GuessDiff), OR(_xlpm.FinalHome=_xlpm.GuessHome, _xlpm.FinalAway=_xlpm.GuessAway) ), 2 +N("Winner and one side score guessed, 2 points"), IF( SIGN(_xlpm.FinalDiff) = SIGN(_xlpm.GuessDiff), 1 +N("Only winner guessed, 1 point"), 0 +N("Wrong guess, 0 points") ) ) ) ) ) -> 0 | T7: 0:4 | U7: =_xlfn.LET( _xlpm.FinalScore, TRIM(SUBSTITUTE($T$6," ","")), _xlpm.UserGuess, TRIM(SUBSTITUTE(T7," ","")), _xlpm.FinalHome, VALUE(LEFT(_xlpm.FinalScore, FIND(":", _xlpm.FinalScore)-1)), _xlpm.FinalAway, VALUE(MID(_xlpm.FinalScore, FIND(":", _xlpm.FinalScore)+1, LEN(_xlpm.FinalScore))), _xlpm.GuessHome, VALUE(LEFT(_xlpm.UserGuess, FIND(":", _xlpm.UserGuess)-1)), _xlpm.GuessAway, VALUE(MID(_xlpm.UserGuess, FIND(":", _xlpm.UserGuess)+1, LEN(_xlpm.UserGuess))), _xlpm.FinalDiff, _xlpm.FinalHome - _xlpm.FinalAway, _xlpm.GuessDiff, _xlpm.GuessHome - _xlpm.GuessAway, IF( OR($T$6="", T7=""), 0 +N("If final or guess is missing, 0 points"), IF( AND(_xlpm.FinalHome=_xlpm.GuessHome, _xlpm.FinalAway=_xlpm.GuessAway), 4 +N("Exact score guessed, 4 points"), IF( AND( SIGN(_xlpm.FinalDiff) = SIGN(_xlpm.GuessDiff), OR(_xlpm.FinalHome=_xlpm.GuessHome, _xlpm.FinalAway=_xlpm.GuessAway) ), 2 +N("Winner and one side score guessed, 2 points"), IF( SIGN(_xlpm.FinalDiff) = SIGN(_xlpm.GuessDiff), 1 +N("Only winner guessed, 1 point"), 0 +N("Wrong guess, 0 points") ) ) ) ) ) -> 0 | V7: 3:2 | W7: =_xlfn.LET( _xlpm.FinalScore, TRIM(SUBSTITUTE($V$6," ","")), _xlpm.UserGuess, TRIM(SUBSTITUTE(V7," ","")), _xlpm.FinalHome, VALUE(LEFT(_xlpm.FinalScore, FIND(":", _xlpm.FinalScore)-1)), _xlpm.FinalAway, VALUE(MID(_xlpm.FinalScore, FIND(":", _xlpm.FinalScore)+1, LEN(_xlpm.FinalScore))), _xlpm.GuessHome, VALUE(LEFT(_xlpm.UserGuess, FIND(":", _xlpm.UserGuess)-1)), _xlpm.GuessAway, VALUE(MID(_xlpm.UserGuess, FIND(":", _xlpm.UserGuess)+1, LEN(_xlpm.UserGuess))), _xlpm.FinalDiff, _xlpm.FinalHome - _xlpm.FinalAway, _xlpm.GuessDiff, _xlpm.GuessHome - _xlpm.GuessAway, IF( OR($V$6="", V7=""), 0 +N("If final or guess is missing, 0 points"), IF( AND(_xlpm.FinalHome=_xlpm.GuessHome, _xlpm.FinalAway=_xlpm.GuessAway), 4 +N("Exact score guessed, 4 points"), IF( AND( SIGN(_xlpm.FinalDiff) = SIGN(_xlpm.GuessDiff), OR(_xlpm.FinalHome=_xlpm.GuessHome, _xlpm.FinalAway=_xlpm.GuessAway) ), 2 +N("Winner and one side score guessed, 2 points"), IF( SIGN(_xlpm.FinalDiff) = SIGN(_xlpm.GuessDiff), 1 +N("Only winner guessed, 1 point"), 0 +N("Wrong guess, 0 points") ) ) ) ) ) -> 0 | Y7: 2:3 | Z7: =_xlfn.LET( _xlpm.FinalScore, TRIM(SUBSTITUTE($Y$6," ","")), _xlpm.UserGuess, TRIM(SUBSTITUTE(Y7," ","")), _xlpm.FinalHome, VALUE(LEFT(_xlpm.FinalScore, FIND(":", _xlpm.FinalScore)-1)), _xlpm.FinalAway, VALUE(MID(_xlpm.FinalScore, FIND(":", _xlpm.FinalScore)+1, LEN(_xlpm.FinalScore))), _xlpm.GuessHome, VALUE(LEFT(_xlpm.UserGuess, FIND(":", _xlpm.UserGuess)-1)), _xlpm.GuessAway, VALUE(MID(_xlpm.UserGuess, FIND(":", _xlpm.UserGuess)+1, LEN(_xlpm.UserGuess))), _xlpm.FinalDiff, _xlpm.FinalHome - _xlpm.FinalAway, _xlpm.GuessDiff, _xlpm.GuessHome - _xlpm.GuessAway, IF( OR($Y$6="", Y7=""), 0 +N("If final or guess is missing, 0 points"), IF( AND(_xlpm.FinalHome=_xlpm.GuessHome, _xlpm.FinalAway=_xlpm.GuessAway), 4 +N("Exact score guessed, 4 points"), IF( AND( SIGN(_xlpm.FinalDiff) = SIGN(_xlpm.GuessDiff), OR(_xlpm.FinalHome=_xlpm.GuessHome, _xlpm.FinalAway=_xlpm.GuessAway) ), 2 +N("Winner and one side score guessed, 2 points"), IF( SIGN(_xlpm.FinalDiff) = SIGN(_xlpm.GuessDiff), 1 +N("Only winner guessed, 1 point"), 0 +N("Wrong guess, 0 points") ) ) ) ) ) -> 0 | AA7: 1:3 | AB7: =_xlfn.LET( _xlpm.FinalScore, TRIM(SUBSTITUTE($AA$6," ","")), _xlpm.UserGuess, TRIM(SUBSTITUTE(AA7," ","")), _xlpm.FinalHome, VALUE(LEFT(_xlpm.FinalScore, FIND(":", _xlpm.FinalScore)-1)), _xlpm.FinalAway, VALUE(MID(_xlpm.FinalScore, FIND(":", _xlpm.FinalScore)+1, LEN(_xlpm.FinalScore))), _xlpm.GuessHome, VALUE(LEFT(_xlpm.UserGuess, FIND(":", _xlpm.UserGuess)-1)), _xlpm.GuessAway, VALUE(MID(_xlpm.UserGuess, FIND(":", _xlpm.UserGuess)+1, LEN(_xlpm.UserGuess))), _xlpm.FinalDiff, _xlpm.FinalHome - _xlpm.FinalAway, _xlpm.GuessDiff, _xlpm.GuessHome - _xlpm.GuessAway, IF( OR($AA$6="", AA7=""), 0 +N("If final or guess is missing, 0 points"), IF( AND(_xlpm.FinalHome=_xlpm.GuessHome, _xlpm.FinalAway=_xlpm.GuessAway), 4 +N("Exact score guessed, 4 points"), IF( AND( SIGN(_xlpm.FinalDiff) = SIGN(_xlpm.GuessDiff), OR(_xlpm.FinalHome=_xlpm.GuessHome, _xlpm.FinalAway=_xlpm.GuessAway) ), 2 +N("Winner and one side score guessed, 2 points"), IF( SIGN(_xlpm.FinalDiff) = SIGN(_xlpm.GuessDiff), 1 +N("Only winner guessed, 1 point"), 0 +N("Wrong guess, 0 points") ) ) ) ) ) -> 0 | AC7: 1:4 | AD7: =_xlfn.LET( _xlpm.FinalScore, TRIM(SUBSTITUTE($AC$6," ","")), _xlpm.UserGuess, TRIM(SUBSTITUTE(AC7," ","")), _xlpm.FinalHome, VALUE(LEFT(_xlpm.FinalScore, FIND(":", _xlpm.FinalScore)-1)), _xlpm.FinalAway, VALUE(MID(_xlpm.FinalScore, FIND(":", _xlpm.FinalScore)+1, LEN(_xlpm.FinalScore))), _xlpm.GuessHome, VALUE(LEFT(_xlpm.UserGuess, FIND(":", _xlpm.UserGuess)-1)), _xlpm.GuessAway, VALUE(MID(_xlpm.UserGuess, FIND(":", _xlpm.UserGuess)+1, LEN(_xlpm.UserGuess))), _xlpm.FinalDiff, _xlpm.FinalHome - _xlpm.FinalAway, _xlpm.GuessDiff, _xlpm.GuessHome - _xlpm.GuessAway, IF( OR($AC$6="", AC7=""), 0 +N("If final or guess is missing, 0 points"), IF( AND(_xlpm.FinalHome=_xlpm.GuessHome, _xlpm.FinalAway=_xlpm.GuessAway), 4 +N("Exact score guessed, 4 points"), IF( AND( SIGN(_xlpm.FinalDiff) = SIGN(_xlpm.GuessDiff), OR(_xlpm.FinalHome=_xlpm.GuessHome, _xlpm.FinalAway=_xlpm.GuessAway) ), 2 +N("Winner and one side score guessed, 2 points"), IF( SIGN(_xlpm.FinalDiff) = SIGN(_xlpm.GuessDiff), 1 +N("Only winner guessed, 1 point"), 0 +N("Wrong guess, 0 points") ) ) ) ) ) -> 0 | AE7: 3:2 | AF7: =_xlfn.LET( _xlpm.FinalScore, TRIM(SUBSTITUTE($AE$6," ","")), _xlpm.UserGuess, TRIM(SUBSTITUTE(AE7," ","")), _xlpm.FinalHome, VALUE(LEFT(_xlpm.FinalScore, FIND(":", _xlpm.FinalScore)-1)), _xlpm.FinalAway, VALUE(MID(_xlpm.FinalScore, FIND(":", _xlpm.FinalScore)+1, LEN(_xlpm.FinalScore))), _xlpm.GuessHome, VALUE(LEFT(_xlpm.UserGuess, FIND(":", _xlpm.UserGuess)-1)), _xlpm.GuessAway, VALUE(MID(_xlpm.UserGuess, FIND(":", _xlpm.UserGuess)+1, LEN(_xlpm.UserGuess))), _xlpm.FinalDiff, _xlpm.FinalHome - _xlpm.FinalAway, _xlpm.GuessDiff, _xlpm.GuessHome - _xlpm.GuessAway, IF( OR($AE$6="", AE7=""), 0 +N("If final or guess is missing, 0 points"), IF( AND(_xlpm.FinalHome=_xlpm.GuessHome, _xlpm.FinalAway=_xlpm.GuessAway), 4 +N("Exact score guessed, 4 points"), IF( AND( SIGN(_xlpm.FinalDiff) = SIGN(_xlpm.GuessDiff), OR(_xlpm.FinalHome=_xlpm.GuessHome, _xlpm.FinalAway=_xlpm.GuessAway) ), 2 +N("Winner and one side score guessed, 2 points"), IF( SIGN(_xlpm.FinalDiff) = SIGN(_xlpm.GuessDiff), 1 +N("Only winner guessed, 1 point"), 0 +N("Wrong guess, 0 points") ) ) ) ) ) -> 0 | AH7: 4:0 | AI7: =_xlfn.LET( _xlpm.FinalScore, TRIM(SUBSTITUTE($AH$6," ","")), _xlpm.UserGuess, TRIM(SUBSTITUTE(AH7," ","")), _xlpm.FinalHome, VALUE(LEFT(_xlpm.FinalScore, FIND(":", _xlpm.FinalScore)-1)), _xlpm.FinalAway, VALUE(MID(_xlpm.FinalScore, FIND(":", _xlpm.FinalScore)+1, LEN(_xlpm.FinalScore))), _xlpm.GuessHome, VALUE(LEFT(_xlpm.UserGuess, FIND(":", _xlpm.UserGuess)-1)), _xlpm.GuessAway, VALUE(MID(_xlpm.UserGuess, FIND(":", _xlpm.UserGuess)+1, LEN(_xlpm.UserGuess))), _xlpm.FinalDiff, _xlpm.FinalHome - _xlpm.FinalAway, _xlpm.GuessDiff, _xlpm.GuessHome - _xlpm.GuessAway, IF( OR($AH$6="", AH7=""), 0 +N("If final or guess is missing, 0 points"), IF( AND(_xlpm.FinalHome=_xlpm.GuessHome, _xlpm.FinalAway=_xlpm.GuessAway), 4 +N("Exact score guessed, 4 points"), IF( AND( SIGN(_xlpm.FinalDiff) = SIGN(_xlpm.GuessDiff), OR(_xlpm.FinalHome=_xlpm.GuessHome, _xlpm.FinalAway=_xlpm.GuessAway) ), 2 +N("Winner and one side score guessed, 2 points"), IF( SIGN(_xlpm.FinalDiff) = SIGN(_xlpm.GuessDiff), 1 +N("Only winner guessed, 1 point"), 0 +N("Wrong guess, 0 points") ) ) ) ) ) -> 0 | AJ7: 3:0 | AK7: =_xlfn.LET( _xlpm.FinalScore,TRIM(SUBSTITUTE($AJ$6," ","")), _xlpm.UserGuess,TRIM(SUBSTITUTE(AJ7," ","")), _xlpm.FinalHome,VALUE(LEFT(_xlpm.FinalScore,FIND(":",_xlpm.FinalScore)-1)), _xlpm.FinalAway,VALUE(MID(_xlpm.FinalScore,FIND(":",_xlpm.FinalScore)+1,LEN(_xlpm.FinalScore))), _xlpm.GuessHome,VALUE(LEFT(_xlpm.UserGuess,FIND(":",_xlpm.UserGuess)-1)), _xlpm.GuessAway,VALUE(MID(_xlpm.UserGuess,FIND(":",_xlpm.UserGuess)+1,LEN(_xlpm.UserGuess))), _xlpm.FinalDiff,_xlpm.FinalHome-_xlpm.FinalAway, _xlpm.GuessDiff,_xlpm.GuessHome-_xlpm.GuessAway, IF( OR($AJ$6="",AJ7=""), 0+N("If final or guess is missing, 0 points"), IF( AND(_xlpm.FinalHome=_xlpm.GuessHome,_xlpm.FinalAway=_xlpm.GuessAway), 4+N("Exact score guessed, 4 points"), IF( AND( SIGN(_xlpm.FinalDiff)=SIGN(_xlpm.GuessDiff), OR(_xlpm.FinalHome=_xlpm.GuessHome,_xlpm.FinalAway=_xlpm.GuessAway) ), 2+N("Winner and one side score guessed, 2 points"), IF( SIGN(_xlpm.FinalDiff)=SIGN(_xlpm.GuessDiff), 1+N("Only winner guessed, 1 point"), 0+N("Wrong guess, 0 points") ) ) ) ) ) -> 0 | AL7: 5:0 | AM7: =_xlfn.LET( _xlpm.FinalScore, TRIM(SUBSTITUTE($AL$6," ","")), _xlpm.UserGuess, TRIM(SUBSTITUTE(AL7," ","")), _xlpm.FinalHome, VALUE(LEFT(_xlpm.FinalScore, FIND(":", _xlpm.FinalScore)-1)), _xlpm.FinalAway, VALUE(MID(_xlpm.FinalScore, FIND(":", _xlpm.FinalScore)+1, LEN(_xlpm.FinalScore))), _xlpm.GuessHome, VALUE(LEFT(_xlpm.UserGuess, FIND(":", _xlpm.UserGuess)-1)), _xlpm.GuessAway, VALUE(MID(_xlpm.UserGuess, FIND(":", _xlpm.UserGuess)+1, LEN(_xlpm.UserGuess))), _xlpm.FinalDiff, _xlpm.FinalHome - _xlpm.FinalAway, _xlpm.GuessDiff, _xlpm.GuessHome - _xlpm.GuessAway, IF( OR($AL$6="", AL7=""), 0 +N("If final or guess is missing, 0 points"), IF( AND(_xlpm.FinalHome=_xlpm.GuessHome, _xlpm.FinalAway=_xlpm.GuessAway), 4 +N("Exact score guessed, 4 points"), IF( AND( SIGN(_xlpm.FinalDiff) = SIGN(_xlpm.GuessDiff), OR(_xlpm.FinalHome=_xlpm.GuessHome, _xlpm.FinalAway=_xlpm.GuessAway) ), 2 +N("Winner and one side score guessed, 2 points"), IF( SIGN(_xlpm.FinalDiff) = SIGN(_xlpm.GuessDiff), 1 +N("Only winner guessed, 1 point"), 0 +N("Wrong guess, 0 points") ) ) ) ) ) -> 0 | AN7: 3:0 | AO7: =_xlfn.LET( _xlpm.FinalScore, TRIM(SUBSTITUTE($AN$6," ","")), _xlpm.UserGuess, TRIM(SUBSTITUTE(AN7," ","")), _xlpm.FinalHome, VALUE(LEFT(_xlpm.FinalScore, FIND(":", _xlpm.FinalScore)-1)), _xlpm.FinalAway, VALUE(MID(_xlpm.FinalScore, FIND(":", _xlpm.FinalScore)+1, LEN(_xlpm.FinalScore))), _xlpm.GuessHome, VALUE(LEFT(_xlpm.UserGuess, FIND(":", _xlpm.UserGuess)-1)), _xlpm.GuessAway, VALUE(MID(_xlpm.UserGuess, FIND(":", _xlpm.UserGuess)+1, LEN(_xlpm.UserGuess))), _xlpm.FinalDiff, _xlpm.FinalHome - _xlpm.FinalAway, _xlpm.GuessDiff, _xlpm.GuessHome - _xlpm.GuessAway, IF( OR($AN$6="", AN7=""), 0 +N("If final or guess is missing, 0 points"), IF( AND(_xlpm.FinalHome=_xlpm.GuessHome, _xlpm.FinalAway=_xlpm.GuessAway), 4 +N("Exact score guessed, 4 points"), IF( AND( SIGN(_xlpm.FinalDiff) = SIGN(_xlpm.GuessDiff), OR(_xlpm.FinalHome=_xlpm.GuessHome, _xlpm.FinalAway=_xlpm.GuessAway) ), 2 +N("Winner and one side score guessed, 2 points"), IF( SIGN(_xlpm.FinalDiff) = SIGN(_xlpm.GuessDiff), 1 +N("Only winner guessed, 1 point"), 0 +N("Wrong guess, 0 points") ) ) ) ) ) -> 0 | AQ7: 3:1 | AR7: =_xlfn.LET( _xlpm.FinalScore, TRIM(SUBSTITUTE($AQ$6," ","")), _xlpm.UserGuess, TRIM(SUBSTITUTE(AQ7," ","")), _xlpm.FinalHome, VALUE(LEFT(_xlpm.FinalScore, FIND(":", _xlpm.FinalScore)-1)), _xlpm.FinalAway, VALUE(MID(_xlpm.FinalScore, FIND(":", _xlpm.FinalScore)+1, LEN(_xlpm.FinalScore))), _xlpm.GuessHome, VALUE(LEFT(_xlpm.UserGuess, FIND(":", _xlpm.UserGuess)-1)), _xlpm.GuessAway, VALUE(MID(_xlpm.UserGuess, FIND(":", _xlpm.UserGuess)+1, LEN(_xlpm.UserGuess))), _xlpm.FinalDiff, _xlpm.FinalHome - _xlpm.FinalAway, _xlpm.GuessDiff, _xlpm.GuessHome - _xlpm.GuessAway, IF( OR($AQ$6="", AQ7=""), 0 +N("If final or guess is missing, 0 points"), IF( AND(_xlpm.FinalHome=_xlpm.GuessHome, _xlpm.FinalAway=_xlpm.GuessAway), 4 +N("Exact score guessed, 4 points"), IF( AND( SIGN(_xlpm.FinalDiff) = SIGN(_xlpm.GuessDiff), OR(_xlpm.FinalHome=_xlpm.GuessHome, _xlpm.FinalAway=_xlpm.GuessAway) ), 2 +N("Winner and one side score guessed, 2 points"), IF( SIGN(_xlpm.FinalDiff) = SIGN(_xlpm.GuessDiff), 1 +N("Only winner guessed, 1 point"), 0 +N("Wrong guess, 0 points") ) ) ) ) ) -> 0 | AS7: 5:0 | AT7: =_xlfn.LET( _xlpm.FinalScore, TRIM(SUBSTITUTE($AS$6," ","")), _xlpm.UserGuess, TRIM(SUBSTITUTE(AS7," ","")), _xlpm.FinalHome, VALUE(LEFT(_xlpm.FinalScore, FIND(":", _xlpm.FinalScore)-1)), _xlpm.FinalAway, VALUE(MID(_xlpm.FinalScore, FIND(":", _xlpm.FinalScore)+1, LEN(_xlpm.FinalScore))), _xlpm.GuessHome, VALUE(LEFT(_xlpm.UserGuess, FIND(":", _xlpm.UserGuess)-1)), _xlpm.GuessAway, VALUE(MID(_xlpm.UserGuess, FIND(":", _xlpm.UserGuess)+1, LEN(_xlpm.UserGuess))), _xlpm.FinalDiff, _xlpm.FinalHome - _xlpm.FinalAway, _xlpm.GuessDiff, _xlpm.GuessHome - _xlpm.GuessAway, IF( OR($AS$6="", AS7=""), 0 +N("If final or guess is missing, 0 points"), IF( AND(_xlpm.FinalHome=_xlpm.GuessHome, _xlpm.FinalAway=_xlpm.GuessAway), 4 +N("Exact score guessed, 4 points"), IF( AND( SIGN(_xlpm.FinalDiff) = SIGN(_xlpm.GuessDiff), OR(_xlpm.FinalHome=_xlpm.GuessHome, _xlpm.FinalAway=_xlpm.GuessAway) ), 2 +N("Winner and one side score guessed, 2 points"), IF( SIGN(_xlpm.FinalDiff) = SIGN(_xlpm.GuessDiff), 1 +N("Only winner guessed, 1 point"), 0 +N("Wrong guess, 0 points") ) ) ) ) ) -> 0 | AU7: 1:2 | AV7: =_xlfn.LET( _xlpm.FinalScore, TRIM(SUBSTITUTE($AU$6," ","")), _xlpm.UserGuess, TRIM(SUBSTITUTE(AU7," ","")), _xlpm.FinalHome, VALUE(LEFT(_xlpm.FinalScore, FIND(":", _xlpm.FinalScore)-1)), _xlpm.FinalAway, VALUE(MID(_xlpm.FinalScore, FIND(":", _xlpm.FinalScore)+1, LEN(_xlpm.FinalScore))), _xlpm.GuessHome, VALUE(LEFT(_xlpm.UserGuess, FIND(":", _xlpm.UserGuess)-1)), _xlpm.GuessAway, VALUE(MID(_xlpm.UserGuess, FIND(":", _xlpm.UserGuess)+1, LEN(_xlpm.UserGuess))), _xlpm.FinalDiff, _xlpm.FinalHome - _xlpm.FinalAway, _xlpm.GuessDiff, _xlpm.GuessHome - _xlpm.GuessAway, IF( OR($AU$6="", AU7=""), 0 +N("If final or guess is missing, 0 points"), IF( AND(_xlpm.FinalHome=_xlpm.GuessHome, _xlpm.FinalAway=_xlpm.GuessAway), 4 +N("Exact score guessed, 4 points"), IF( AND( SIGN(_xlpm.FinalDiff) = SIGN(_xlpm.GuessDiff), OR(_xlpm.FinalHome=_xlpm.GuessHome, _xlpm.FinalAway=_xlpm.GuessAway) ), 2 +N("Winner and one side score guessed, 2 points"), IF( SIGN(_xlpm.FinalDiff) = SIGN(_xlpm.GuessDiff), 1 +N("Only winner guessed, 1 point"), 0 +N("Wrong guess, 0 points") ) ) ) ) ) -> 0 | AW7: 4:1 | AX7: =_xlfn.LET( _xlpm.FinalScore, TRIM(SUBSTITUTE($AW$6," ","")), _xlpm.UserGuess, TRIM(SUBSTITUTE(AW7," ","")), _xlpm.FinalHome, VALUE(LEFT(_xlpm.FinalScore, FIND(":", _xlpm.FinalScore)-1)), _xlpm.FinalAway, VALUE(MID(_xlpm.FinalScore, FIND(":", _xlpm.FinalScore)+1, LEN(_xlpm.FinalScore))), _xlpm.GuessHome, VALUE(LEFT(_xlpm.UserGuess, FIND(":", _xlpm.UserGuess)-1)), _xlpm.GuessAway, VALUE(MID(_xlpm.UserGuess, FIND(":", _xlpm.UserGuess)+1, LEN(_xlpm.UserGuess))), _xlpm.FinalDiff, _xlpm.FinalHome - _xlpm.FinalAway, _xlpm.GuessDiff, _xlpm.GuessHome - _xlpm.GuessAway, IF( OR($AW$6="", AW7=""), 0 +N("If final or guess is missing, 0 points"), IF( AND(_xlpm.FinalHome=_xlpm.GuessHome, _xlpm.FinalAway=_xlpm.GuessAway), 4 +N("Exact score guessed, 4 points"), IF( AND( SIGN(_xlpm.FinalDiff) = SIGN(_xlpm.GuessDiff), OR(_xlpm.FinalHome=_xlpm.GuessHome, _xlpm.FinalAway=_xlpm.GuessAway) ), 2 +N("Winner and one side score guessed, 2 points"), IF( SIGN(_xlpm.FinalDiff) = SIGN(_xlpm.GuessDiff), 1 +N("Only winner guessed, 1 point"), 0 +N("Wrong guess, 0 points") ) ) ) ) ) -> 0 | BA7: =_xlfn.LET( _xlpm.FinalScore, TRIM(SUBSTITUTE($AW$6," ","")), _xlpm.UserGuess, TRIM(SUBSTITUTE(AZ7," ","")), _xlpm.FinalHome, VALUE(LEFT(_xlpm.FinalScore, FIND(":", _xlpm.FinalScore)-1)), _xlpm.FinalAway, VALUE(MID(_xlpm.FinalScore, FIND(":", _xlpm.FinalScore)+1, LEN(_xlpm.FinalScore))), _xlpm.GuessHome, VALUE(LEFT(_xlpm.UserGuess, FIND(":", _xlpm.UserGuess)-1)), _xlpm.GuessAway, VALUE(MID(_xlpm.UserGuess, FIND(":", _xlpm.UserGuess)+1, LEN(_xlpm.UserGuess))), _xlpm.FinalDiff, _xlpm.FinalHome - _xlpm.FinalAway, _xlpm.GuessDiff, _xlpm.GuessHome - _xlpm.GuessAway, IF( OR($AW$6="", AZ7=""), 0 +N("If final or guess is missing, 0 points"), IF( AND(_xlpm.FinalHome=_xlpm.GuessHome, _xlpm.FinalAway=_xlpm.GuessAway), 5 +N("Exact score guessed, 5 points"), IF( AND( SIGN(_xlpm.FinalDiff) = SIGN(_xlpm.GuessDiff), OR(_xlpm.FinalHome=_xlpm.GuessHome, _xlpm.FinalAway=_xlpm.GuessAway) ), 3 +N("Winner and one side score guessed, 3 points"), IF( SIGN(_xlpm.FinalDiff) = SIGN(_xlpm.GuessDiff), 2 +N("Only winner guessed, 2 point"), 0 +N("Wrong guess, 0 points") ) ) ) ) ) -> 0 | BC7: =_xlfn.LET( _xlpm.FinalScore, TRIM(SUBSTITUTE($AW$6," ","")), _xlpm.UserGuess, TRIM(SUBSTITUTE(BB7," ","")), _xlpm.FinalHome, VALUE(LEFT(_xlpm.FinalScore, FIND(":", _xlpm.FinalScore)-1)), _xlpm.FinalAway, VALUE(MID(_xlpm.FinalScore, FIND(":", _xlpm.FinalScore)+1, LEN(_xlpm.FinalScore))), _xlpm.GuessHome, VALUE(LEFT(_xlpm.UserGuess, FIND(":", _xlpm.UserGuess)-1)), _xlpm.GuessAway, VALUE(MID(_xlpm.UserGuess, FIND(":", _xlpm.UserGuess)+1, LEN(_xlpm.UserGuess))), _xlpm.FinalDiff, _xlpm.FinalHome - _xlpm.FinalAway, _xlpm.GuessDiff, _xlpm.GuessHome - _xlpm.GuessAway, IF( OR($AW$6="", BB7=""), 0 +N("If final or guess is missing, 0 points"), IF( AND(_xlpm.FinalHome=_xlpm.GuessHome, _xlpm.FinalAway=_xlpm.GuessAway), 5 +N("Exact score guessed, 5 points"), IF( AND( SIGN(_xlpm.FinalDiff) = SIGN(_xlpm.GuessDiff), OR(_xlpm.FinalHome=_xlpm.GuessHome, _xlpm.FinalAway=_xlpm.GuessAway) ), 3 +N("Winner and one side score guessed, 3 points"), IF( SIGN(_xlpm.FinalDiff) = SIGN(_xlpm.GuessDiff), 2 +N("Only winner guessed, 2 point"), 0 +N("Wrong guess, 0 points") ) ) ) ) ) -> 0 | BE7: =_xlfn.LET( _xlpm.FinalScore, TRIM(SUBSTITUTE($AW$6," ","")), _xlpm.UserGuess, TRIM(SUBSTITUTE(BD7," ","")), _xlpm.FinalHome, VALUE(LEFT(_xlpm.FinalScore, FIND(":", _xlpm.FinalScore)-1)), _xlpm.FinalAway, VALUE(MID(_xlpm.FinalScore, FIND(":", _xlpm.FinalScore)+1, LEN(_xlpm.FinalScore))), _xlpm.GuessHome, VALUE(LEFT(_xlpm.UserGuess, FIND(":", _xlpm.UserGuess)-1)), _xlpm.GuessAway, VALUE(MID(_xlpm.UserGuess, FIND(":", _xlpm.UserGuess)+1, LEN(_xlpm.UserGuess))), _xlpm.FinalDiff, _xlpm.FinalHome - _xlpm.FinalAway, _xlpm.GuessDiff, _xlpm.GuessHome - _xlpm.GuessAway, IF( OR($AW$6="", BD7=""), 0 +N("If final or guess is missing, 0 points"), IF( AND(_xlpm.FinalHome=_xlpm.GuessHome, _xlpm.FinalAway=_xlpm.GuessAway), 5 +N("Exact score guessed, 5 points"), IF( AND( SIGN(_xlpm.FinalDiff) = SIGN(_xlpm.GuessDiff), OR(_xlpm.FinalHome=_xlpm.GuessHome, _xlpm.FinalAway=_xlpm.GuessAway) ), 3 +N("Winner and one side score guessed, 3 points"), IF( SIGN(_xlpm.FinalDiff) = SIGN(_xlpm.GuessDiff), 2 +N("Only winner guessed, 2 point"), 0 +N("Wrong guess, 0 points") ) ) ) ) ) -> 0 | BG7: =_xlfn.LET( _xlpm.FinalScore, TRIM(SUBSTITUTE($AW$6," ","")), _xlpm.UserGuess, TRIM(SUBSTITUTE(BF7," ","")), _xlpm.FinalHome, VALUE(LEFT(_xlpm.FinalScore, FIND(":", _xlpm.FinalScore)-1)), _xlpm.FinalAway, VALUE(MID(_xlpm.FinalScore, FIND(":", _xlpm.FinalScore)+1, LEN(_xlpm.FinalScore))), _xlpm.GuessHome, VALUE(LEFT(_xlpm.UserGuess, FIND(":", _xlpm.UserGuess)-1)), _xlpm.GuessAway, VALUE(MID(_xlpm.UserGuess, FIND(":", _xlpm.UserGuess)+1, LEN(_xlpm.UserGuess))), _xlpm.FinalDiff, _xlpm.FinalHome - _xlpm.FinalAway, _xlpm.GuessDiff, _xlpm.GuessHome - _xlpm.GuessAway, IF( OR($AW$6="", BF7=""), 0 +N("If final or guess is missing, 0 points"), IF( AND(_xlpm.FinalHome=_xlpm.GuessHome, _xlpm.FinalAway=_xlpm.GuessAway), 5 +N("Exact score guessed, 5 points"), IF( AND( SIGN(_xlpm.FinalDiff) = SIGN(_xlpm.GuessDiff), OR(_xlpm.FinalHome=_xlpm.GuessHome, _xlpm.FinalAway=_xlpm.GuessAway) ), 3 +N("Winner and one side score guessed, 3 points"), IF( SIGN(_xlpm.FinalDiff) = SIGN(_xlpm.GuessDiff), 2 +N("Only winner guessed, 2 point"), 0 +N("Wrong guess, 0 points") ) ) ) ) ) -> 0 | BJ7: =_xlfn.LET( _xlpm.FinalScore, TRIM(SUBSTITUTE($AW$6," ","")), _xlpm.UserGuess, TRIM(SUBSTITUTE(BI7," ","")), _xlpm.FinalHome, VALUE(LEFT(_xlpm.FinalScore, FIND(":", _xlpm.FinalScore)-1)), _xlpm.FinalAway, VALUE(MID(_xlpm.FinalScore, FIND(":", _xlpm.FinalScore)+1, LEN(_xlpm.FinalScore))), _xlpm.GuessHome, VALUE(LEFT(_xlpm.UserGuess, FIND(":", _xlpm.UserGuess)-1)), _xlpm.GuessAway, VALUE(MID(_xlpm.UserGuess, FIND(":", _xlpm.UserGuess)+1, LEN(_xlpm.UserGuess))), _xlpm.FinalDiff, _xlpm.FinalHome - _xlpm.FinalAway, _xlpm.GuessDiff, _xlpm.GuessHome - _xlpm.GuessAway, IF( OR($AW$6="", BI7=""), 0 +N("If final or guess is missing, 0 points"), IF( AND(_xlpm.FinalHome=_xlpm.GuessHome, _xlpm.FinalAway=_xlpm.GuessAway), 5 +N("Exact score guessed, 5 points"), IF( AND( SIGN(_xlpm.FinalDiff) = SIGN(_xlpm.GuessDiff), OR(_xlpm.FinalHome=_xlpm.GuessHome, _xlpm.FinalAway=_xlpm.GuessAway) ), 3 +N("Winner and one side score guessed, 3 points"), IF( SIGN(_xlpm.FinalDiff) = SIGN(_xlpm.GuessDiff), 2 +N("Only winner guessed, 2 point"), 0 +N("Wrong guess, 0 points") ) ) ) ) ) -> 0 | BL7: =_xlfn.LET( _xlpm.FinalScore, TRIM(SUBSTITUTE($AW$6," ","")), _xlpm.UserGuess, TRIM(SUBSTITUTE(BK7," ","")), _xlpm.FinalHome, VALUE(LEFT(_xlpm.FinalScore, FIND(":", _xlpm.FinalScore)-1)), _xlpm.FinalAway, VALUE(MID(_xlpm.FinalScore, FIND(":", _xlpm.FinalScore)+1, LEN(_xlpm.FinalScore))), _xlpm.GuessHome, VALUE(LEFT(_xlpm.UserGuess, FIND(":", _xlpm.UserGuess)-1)), _xlpm.GuessAway, VALUE(MID(_xlpm.UserGuess, FIND(":", _xlpm.UserGuess)+1, LEN(_xlpm.UserGuess))), _xlpm.FinalDiff, _xlpm.FinalHome - _xlpm.FinalAway, _xlpm.GuessDiff, _xlpm.GuessHome - _xlpm.GuessAway, IF( OR($AW$6="", BK7=""), 0 +N("If final or guess is missing, 0 points"), IF( AND(_xlpm.FinalHome=_xlpm.GuessHome, _xlpm.FinalAway=_xlpm.GuessAway), 5 +N("Exact score guessed, 5 points"), IF( AND( SIGN(_xlpm.FinalDiff) = SIGN(_xlpm.GuessDiff), OR(_xlpm.FinalHome=_xlpm.GuessHome, _xlpm.FinalAway=_xlpm.GuessAway) ), 3 +N("Winner and one side score guessed, 3 points"), IF( SIGN(_xlpm.FinalDiff) = SIGN(_xlpm.GuessDiff), 2 +N("Only winner guessed, 2 point"), 0 +N("Wrong guess, 0 points") ) ) ) ) ) -> 0 | BN7: =_xlfn.LET( _xlpm.FinalScore, TRIM(SUBSTITUTE($AW$6," ","")), _xlpm.UserGuess, TRIM(SUBSTITUTE(BM7," ","")), _xlpm.FinalHome, VALUE(LEFT(_xlpm.FinalScore, FIND(":", _xlpm.FinalScore)-1)), _xlpm.FinalAway, VALUE(MID(_xlpm.FinalScore, FIND(":", _xlpm.FinalScore)+1, LEN(_xlpm.FinalScore))), _xlpm.GuessHome, VALUE(LEFT(_xlpm.UserGuess, FIND(":", _xlpm.UserGuess)-1)), _xlpm.GuessAway, VALUE(MID(_xlpm.UserGuess, FIND(":", _xlpm.UserGuess)+1, LEN(_xlpm.UserGuess))), _xlpm.FinalDiff, _xlpm.FinalHome - _xlpm.FinalAway, _xlpm.GuessDiff, _xlpm.GuessHome - _xlpm.GuessAway, IF( OR($AW$6="", BM7=""), 0 +N("If final or guess is missing, 0 points"), IF( AND(_xlpm.FinalHome=_xlpm.GuessHome, _xlpm.FinalAway=_xlpm.GuessAway), 5 +N("Exact score guessed, 5 points"), IF( AND( SIGN(_xlpm.FinalDiff) = SIGN(_xlpm.GuessDiff), OR(_xlpm.FinalHome=_xlpm.GuessHome, _xlpm.FinalAway=_xlpm.GuessAway) ), 3 +N("Winner and one side score guessed, 3 points"), IF( SIGN(_xlpm.FinalDiff) = SIGN(_xlpm.GuessDiff), 2 +N("Only winner guessed, 2 point"), 0 +N("Wrong guess, 0 points") ) ) ) ) ) -> 0 | BP7: =_xlfn.LET( _xlpm.FinalScore, TRIM(SUBSTITUTE($AW$6," ","")), _xlpm.UserGuess, TRIM(SUBSTITUTE(BO7," ","")), _xlpm.FinalHome, VALUE(LEFT(_xlpm.FinalScore, FIND(":", _xlpm.FinalScore)-1)), _xlpm.FinalAway, VALUE(MID(_xlpm.FinalScore, FIND(":", _xlpm.FinalScore)+1, LEN(_xlpm.FinalScore))), _xlpm.GuessHome, VALUE(LEFT(_xlpm.UserGuess, FIND(":", _xlpm.UserGuess)-1)), _xlpm.GuessAway, VALUE(MID(_xlpm.UserGuess, FIND(":", _xlpm.UserGuess)+1, LEN(_xlpm.UserGuess))), _xlpm.FinalDiff, _xlpm.FinalHome - _xlpm.FinalAway, _xlpm.GuessDiff, _xlpm.GuessHome - _xlpm.GuessAway, IF( OR($AW$6="", BO7=""), 0 +N("If final or guess is missing, 0 points"), IF( AND(_xlpm.FinalHome=_xlpm.GuessHome, _xlpm.FinalAway=_xlpm.GuessAway), 5 +N("Exact score guessed, 5 points"), IF( AND( SIGN(_xlpm.FinalDiff) = SIGN(_xlpm.GuessDiff), OR(_xlpm.FinalHome=_xlpm.GuessHome, _xlpm.FinalAway=_xlpm.GuessAway) ), 3 +N("Winner and one side score guessed, 3 points"), IF( SIGN(_xlpm.FinalDiff) = SIGN(_xlpm.GuessDiff), 2 +N("Only winner guessed, 2 point"), 0 +N("Wrong guess, 0 points") ) ) ) ) ) -> 0 | BS7: =_xlfn.LET( _xlpm.FinalScore, TRIM(SUBSTITUTE($AW$6," ","")), _xlpm.UserGuess, TRIM(SUBSTITUTE(BR7," ","")), _xlpm.FinalHome, VALUE(LEFT(_xlpm.FinalScore, FIND(":", _xlpm.FinalScore)-1)), _xlpm.FinalAway, VALUE(MID(_xlpm.FinalScore, FIND(":", _xlpm.FinalScore)+1, LEN(_xlpm.FinalScore))), _xlpm.GuessHome, VALUE(LEFT(_xlpm.UserGuess, FIND(":", _xlpm.UserGuess)-1)), _xlpm.GuessAway, VALUE(MID(_xlpm.UserGuess, FIND(":", _xlpm.UserGuess)+1, LEN(_xlpm.UserGuess))), _xlpm.FinalDiff, _xlpm.FinalHome - _xlpm.FinalAway, _xlpm.GuessDiff, _xlpm.GuessHome - _xlpm.GuessAway, IF( OR($AW$6="", BR7=""), 0 +N("If final or guess is missing, 0 points"), IF( AND(_xlpm.FinalHome=_xlpm.GuessHome, _xlpm.FinalAway=_xlpm.GuessAway), 5 +N("Exact score guessed, 5 points"), IF( AND( SIGN(_xlpm.FinalDiff) = SIGN(_xlpm.GuessDiff), OR(_xlpm.FinalHome=_xlpm.GuessHome, _xlpm.FinalAway=_xlpm.GuessAway) ), 3 +N("Winner and one side score guessed, 3 points"), IF( SIGN(_xlpm.FinalDiff) = SIGN(_xlpm.GuessDiff), 2 +N("Only winner guessed, 2 point"), 0 +N("Wrong guess, 0 points") ) ) ) ) ) -> 0 | BU7: =_xlfn.LET( _xlpm.FinalScore, TRIM(SUBSTITUTE($AW$6," ","")), _xlpm.UserGuess, TRIM(SUBSTITUTE(BT7," ","")), _xlpm.FinalHome, VALUE(LEFT(_xlpm.FinalScore, FIND(":", _xlpm.FinalScore)-1)), _xlpm.FinalAway, VALUE(MID(_xlpm.FinalScore, FIND(":", _xlpm.FinalScore)+1, LEN(_xlpm.FinalScore))), _xlpm.GuessHome, VALUE(LEFT(_xlpm.UserGuess, FIND(":", _xlpm.UserGuess)-1)), _xlpm.GuessAway, VALUE(MID(_xlpm.UserGuess, FIND(":", _xlpm.UserGuess)+1, LEN(_xlpm.UserGuess))), _xlpm.FinalDiff, _xlpm.FinalHome - _xlpm.FinalAway, _xlpm.GuessDiff, _xlpm.GuessHome - _xlpm.GuessAway, IF( OR($AW$6="", BT7=""), 0 +N("If final or guess is missing, 0 points"), IF( AND(_xlpm.FinalHome=_xlpm.GuessHome, _xlpm.FinalAway=_xlpm.GuessAway), 5 +N("Exact score guessed, 5 points"), IF( AND( SIGN(_xlpm.FinalDiff) = SIGN(_xlpm.GuessDiff), OR(_xlpm.FinalHome=_xlpm.GuessHome, _xlpm.FinalAway=_xlpm.GuessAway) ), 3 +N("Winner and one side score guessed, 3 points"), IF( SIGN(_xlpm.FinalDiff) = SIGN(_xlpm.GuessDiff), 2 +N("Only winner guessed, 2 point"), 0 +N("Wrong guess, 0 points") ) ) ) ) ) -> 0 | BX7: =_xlfn.LET( _xlpm.FinalScore, TRIM(SUBSTITUTE($AW$6," ","")), _xlpm.UserGuess, TRIM(SUBSTITUTE(BW7," ","")), _xlpm.FinalHome, VALUE(LEFT(_xlpm.FinalScore, FIND(":", _xlpm.FinalScore)-1)), _xlpm.FinalAway, VALUE(MID(_xlpm.FinalScore, FIND(":", _xlpm.FinalScore)+1, LEN(_xlpm.FinalScore))), _xlpm.GuessHome, VALUE(LEFT(_xlpm.UserGuess, FIND(":", _xlpm.UserGuess)-1)), _xlpm.GuessAway, VALUE(MID(_xlpm.UserGuess, FIND(":", _xlpm.UserGuess)+1, LEN(_xlpm.UserGuess))), _xlpm.FinalDiff, _xlpm.FinalHome - _xlpm.FinalAway, _xlpm.GuessDiff, _xlpm.GuessHome - _xlpm.GuessAway, IF( OR($AW$6="", BW7=""), 0 +N("If final or guess is missing, 0 points"), IF( AND(_xlpm.FinalHome=_xlpm.GuessHome, _xlpm.FinalAway=_xlpm.GuessAway), 5 +N("Exact score guessed, 5 points"), IF( AND( SIGN(_xlpm.FinalDiff) = SIGN(_xlpm.GuessDiff), OR(_xlpm.FinalHome=_xlpm.GuessHome, _xlpm.FinalAway=_xlpm.GuessAway) ), 3 +N("Winner and one side score guessed, 3 points"), IF( SIGN(_xlpm.FinalDiff) = SIGN(_xlpm.GuessDiff), 2 +N("Only winner guessed, 2 point"), 0 +N("Wrong guess, 0 points") ) ) ) ) ) -> 0 | CA7: =_xlfn.LET( _xlpm.FinalScore, TRIM(SUBSTITUTE($AW$6," ","")), _xlpm.UserGuess, TRIM(SUBSTITUTE(BZ7," ","")), _xlpm.FinalHome, VALUE(LEFT(_xlpm.FinalScore, FIND(":", _xlpm.FinalScore)-1)), _xlpm.FinalAway, VALUE(MID(_xlpm.FinalScore, FIND(":", _xlpm.FinalScore)+1, LEN(_xlpm.FinalScore))), _xlpm.GuessHome, VALUE(LEFT(_xlpm.UserGuess, FIND(":", _xlpm.UserGuess)-1)), _xlpm.GuessAway, VALUE(MID(_xlpm.UserGuess, FIND(":", _xlpm.UserGuess)+1, LEN(_xlpm.UserGuess))), _xlpm.FinalDiff, _xlpm.FinalHome - _xlpm.FinalAway, _xlpm.GuessDiff, _xlpm.GuessHome - _xlpm.GuessAway, IF( OR($AW$6="", BZ7=""), 0 +N("If final or guess is missing, 0 points"), IF( AND(_xlpm.FinalHome=_xlpm.GuessHome, _xlpm.FinalAway=_xlpm.GuessAway), 5 +N("Exact score guessed, 5 points"), IF( AND( SIGN(_xlpm.FinalDiff) = SIGN(_xlpm.GuessDiff), OR(_xlpm.FinalHome=_xlpm.GuessHome, _xlpm.FinalAway=_xlpm.GuessAway) ), 3 +N("Winner and one side score guessed, 3 points"), IF( SIGN(_xlpm.FinalDiff) = SIGN(_xlpm.GuessDiff), 2 +N("Only winner guessed, 2 point"), 0 +N("Wrong guess, 0 points") ) ) ) ) ) -> 0
